<?xml version="1.0" ?>
<robot xmlns:xacro="http://www.ros.org/wiki/xacro">
  <xacro:include filename="$(find nekonote_description)/urdf/common_constants.xacro"/>
  <xacro:include filename="$(find nekonote_description)/urdf/common_materials.xacro"/>

  <xacro:macro name="end_effector_A" params="prefix">
    <!-- links -->
    <link name="${prefix}gripper_base">
      <visual>
        <origin xyz="0 0 0" rpy="0 0 0"/>
        <geometry>
          <mesh filename="package://nekonote_description/meshes/visual/end_effector_A/HAND1.stl"/>
        </geometry>
        <xacro:material_grey/>
      </visual>
      <collision>
        <origin xyz="0 0 0" rpy="0 0 0"/>
        <geometry>
          <mesh filename="package://nekonote_description/meshes/collision/end_effector_A/HAND1.stl"/>
        </geometry>
      </collision>
      <inertial>
        <origin rpy="0 0 0" xyz="-0.011687 4.8e-05 0.030393"/>
        <mass value="0.094464"/>
        <inertia ixx="9.9436e-05" ixy="1.1831e-07" ixz="-2.354e-05" iyy="0.00011232" iyz="2.5081e-07" izz="8.0987e-05"/>
      </inertial>
    </link>
    <link name="${prefix}gripper_finger">
      <visual>
        <origin xyz="0 0 0" rpy="${m_pi_2} 0 0"/>
        <geometry>
          <mesh filename="package://nekonote_description/meshes/visual/end_effector_A/HAND2.stl"/>
        </geometry>
        <xacro:material_grey/>
      </visual>
      <collision>
        <origin xyz="0 0 0" rpy="${m_pi_2} 0 0"/>
        <geometry>
          <mesh filename="package://nekonote_description/meshes/collision/end_effector_A/HAND2.stl"/>
        </geometry>
      </collision>
      <inertial>
        <origin rpy="0 0 0" xyz="0.009859 0.03583 0.000117"/>
        <mass value="0.023997"/>
        <inertia ixx="1.0078e-05" ixy="3.3380e-07" ixz="4.766e-09" iyy="3.0823e-06" iyz="1.7785e-08" izz="8.9093e-06"/>
      </inertial>
    </link>
    <link name="${prefix}tool0"/>

    <!-- joints -->
    <joint name="${prefix}hand_base-gripper_base" type="fixed">
      <origin xyz="0 0 0" rpy="0 0 0"/>
      <parent link="${prefix}hand_base"/>
      <child link="${prefix}gripper_base"/>
      <axis xyz="0 0 1"/>
    </joint>
    <joint name="${prefix}gripper_joint" type="revolute">
      <origin xyz="0.004 0 0.0155" rpy="0 0 0"/>
      <parent link="${prefix}gripper_base"/>
      <child link="${prefix}gripper_finger"/>
      <axis xyz="0 1 0"/>
      <limit lower="0.01658" upper="1.1576" effort="0" velocity="0"/>
    </joint>
    <joint name="${prefix}gripper_base-tool0" type="fixed">
      <origin xyz="0 0 0.08" rpy="0 0 0" />
      <parent link="${prefix}gripper_base"/>
      <child link="${prefix}tool0"/>
    </joint>
  </xacro:macro>

</robot>
