<?xml version="1.0" ?>
<!-- =================================================================================== -->
<!-- |    This document was autogenerated by xacro from nekonote.urdf.xacro            | -->
<!-- |    EDITING THIS FILE BY HAND IS NOT RECOMMENDED                                 | -->
<!-- =================================================================================== -->
<robot name="nekonote" xmlns:xacro="http://ros.org/wiki/xacro">
  <!-- NEKONOTE Base URDF -->
  <!-- Pi, the ratio of a circle's circumference to its diameter -->
  <!-- Pi divided by two -->
  <!-- Pi divided by four -->
  <!-- links -->
  <link name="base"/>
  <link name="base_link">
    <visual>
      <origin rpy="0 0 0" xyz="0 0 0"/>
      <geometry>
        <mesh filename="package://nekonote_description/meshes/visual/base/BODY.stl"/>
      </geometry>
      <material name="">
        <color rgba="0.3 0.3 0.3 1"/>
      </material>
    </visual>
    <collision>
      <origin rpy="0 0 0" xyz="0 0 0"/>
      <geometry>
        <mesh filename="package://nekonote_description/meshes/collision/base/BODY.stl"/>
      </geometry>
    </collision>
    <inertial>
      <origin rpy="0 0 0" xyz="-0.001239 -0.000962 0.075348"/>
      <mass value="0.851526"/>
      <inertia ixx="0.00234632" ixy="8.864e-09" ixz="-0.00019645" iyy="0.00224923" iyz="6.2667e-06" izz="0.00142133"/>
    </inertial>
  </link>
  <link name="link1">
    <visual>
      <origin rpy="0 0 0" xyz="0 0 0"/>
      <geometry>
        <mesh filename="package://nekonote_description/meshes/visual/base/JOINT1.stl"/>
      </geometry>
      <material name="">
        <color rgba="0.3 0.3 0.3 1"/>
      </material>
    </visual>
    <collision>
      <origin rpy="0 0 0" xyz="0 0 0"/>
      <geometry>
        <mesh filename="package://nekonote_description/meshes/collision/base/JOINT1.stl"/>
      </geometry>
    </collision>
    <inertial>
      <origin rpy="0 0 0" xyz="0.000216 0 0.032195"/>
      <mass value="0.142759"/>
      <inertia ixx="0.00028078" ixy="0" ixz="9.5105e-07" iyy="0.0001153" iyz="0" izz="0.00026862"/>
    </inertial>
  </link>
  <link name="link2">
    <visual>
      <origin rpy="1.570796327 0 0" xyz="0 0 0"/>
      <geometry>
        <mesh filename="package://nekonote_description/meshes/visual/base/JOINT2.stl"/>
      </geometry>
      <material name="">
        <color rgba="0.3 0.3 0.3 1"/>
      </material>
    </visual>
    <collision>
      <origin rpy="1.570796327 0 0" xyz="0 0 0"/>
      <geometry>
        <mesh filename="package://nekonote_description/meshes/collision/base/JOINT2.stl"/>
      </geometry>
    </collision>
    <inertial>
      <origin rpy="0 0 0" xyz="-0.002309 0.098761 0.00174"/>
      <mass value="0.983205"/>
      <inertia ixx="0.00556176" ixy="-0.00010003" ixz="-3.951e-06" iyy="0.00101996" iyz="-2.650e-05" izz="0.00513079"/>
    </inertial>
  </link>
  <link name="link3">
    <visual>
      <origin rpy="1.570796327 0 0" xyz="0 0 0"/>
      <geometry>
        <mesh filename="package://nekonote_description/meshes/visual/base/JOINT3.stl"/>
      </geometry>
      <material name="">
        <color rgba="0.3 0.3 0.3 1"/>
      </material>
    </visual>
    <collision>
      <origin rpy="1.570796327 0 0" xyz="0 0 0"/>
      <geometry>
        <mesh filename="package://nekonote_description/meshes/collision/base/JOINT3.stl"/>
      </geometry>
    </collision>
    <inertial>
      <origin rpy="0 0 0" xyz="-0.00312 0.08754 -0.00187"/>
      <mass value="0.552063"/>
      <inertia ixx="0.00081437" ixy="-6.414e-06" ixz="3.2409e-06" iyy="0.00039933" iyz="-2.038e-05" izz="0.0007055"/>
    </inertial>
  </link>
  <link name="link4">
    <visual>
      <origin rpy="0 0 0" xyz="0 0 0"/>
      <geometry>
        <mesh filename="package://nekonote_description/meshes/visual/base/JOINT4.stl"/>
      </geometry>
      <material name="">
        <color rgba="0.3 0.3 0.3 1"/>
      </material>
    </visual>
    <collision>
      <origin rpy="0 0 0" xyz="0 0 0"/>
      <geometry>
        <mesh filename="package://nekonote_description/meshes/collision/base/JOINT4.stl"/>
      </geometry>
    </collision>
    <inertial>
      <origin rpy="0 0 0" xyz="0.00227 0.00484 0.04053"/>
      <mass value="0.431401"/>
      <inertia ixx="0.0004845" ixy="7.7315e-06" ixz="-4.916e-06" iyy="0.00036954" iyz="3.8537e-05" izz="0.00039301"/>
    </inertial>
  </link>
  <link name="link5">
    <visual>
      <origin rpy="1.570796327 0 0" xyz="0 0 0"/>
      <geometry>
        <mesh filename="package://nekonote_description/meshes/visual/base/JOINT5.stl"/>
      </geometry>
      <material name="">
        <color rgba="0.3 0.3 0.3 1"/>
      </material>
    </visual>
    <collision>
      <origin rpy="1.570796327 0 0" xyz="0 0 0"/>
      <geometry>
        <mesh filename="package://nekonote_description/meshes/collision/base/JOINT5.stl"/>
      </geometry>
    </collision>
    <inertial>
      <origin rpy="0 0 0" xyz="0.001918 0.009121 -0.003233"/>
      <mass value="0.516153"/>
      <inertia ixx="0.00048104" ixy="2.5913e-05" ixz="-3.218e-06" iyy="0.00033885" iyz="-1.728e-05" izz="0.00051335"/>
    </inertial>
  </link>
  <link name="hand_base"/>
  <!-- joints -->
  <joint name="base_link-base" type="fixed">
    <origin rpy="0 0 0" xyz="0 0 0"/>
    <parent link="base_link"/>
    <child link="base"/>
  </joint>
  <joint name="joint0" type="revolute">
    <origin rpy="0 0 0" xyz="0 0 0.131"/>
    <parent link="base_link"/>
    <child link="link1"/>
    <axis xyz="0 0 1"/>
    <limit effort="0" lower="-1.7453" upper="1.7453" velocity="0"/>
  </joint>
  <joint name="joint1" type="revolute">
    <origin rpy="0 0 0" xyz="0 0 0.044"/>
    <parent link="link1"/>
    <child link="link2"/>
    <axis xyz="0 1 0"/>
    <limit effort="0" lower="-1.57" upper="1.57" velocity="0"/>
  </joint>
  <joint name="joint2" type="revolute">
    <origin rpy="0 0 0" xyz="0 0 0.1825"/>
    <parent link="link2"/>
    <child link="link3"/>
    <axis xyz="0 1 0"/>
    <limit effort="0" lower="-1.8353" upper="2.5837" velocity="0"/>
  </joint>
  <joint name="joint3" type="revolute">
    <origin rpy="0 0 0" xyz="0 0 0.1305"/>
    <parent link="link3"/>
    <child link="link4"/>
    <axis xyz="0 0 1"/>
    <limit effort="0" lower="-1.7453" upper="1.7453" velocity="0"/>
  </joint>
  <joint name="joint4" type="revolute">
    <origin rpy="0 0 0" xyz="0 0 0.117"/>
    <parent link="link4"/>
    <child link="link5"/>
    <axis xyz="0 -1 0"/>
    <limit effort="0" lower="-1.57" upper="1.57" velocity="0"/>
  </joint>
  <joint name="joint5" type="revolute">
    <origin rpy="0 0 0" xyz="0 0 0.045"/>
    <parent link="link5"/>
    <child link="hand_base"/>
    <axis xyz="0 0 -1"/>
    <limit effort="0" lower="-1.7453" upper="1.7453" velocity="0"/>
  </joint>
  <!-- End Effector -->
  <!-- Pi, the ratio of a circle's circumference to its diameter -->
  <!-- Pi divided by two -->
  <!-- Pi divided by four -->
  <!-- links -->
  <link name="hand1">
    <visual>
      <origin rpy="0 0 0" xyz="0 0 0"/>
      <geometry>
        <mesh filename="package://nekonote_description/meshes/visual/end_effector_A/HAND1.stl"/>
      </geometry>
      <material name="">
        <color rgba="0.3 0.3 0.3 1"/>
      </material>
    </visual>
    <collision>
      <origin rpy="0 0 0" xyz="0 0 0"/>
      <geometry>
        <mesh filename="package://nekonote_description/meshes/collision/end_effector_A/HAND1.stl"/>
      </geometry>
    </collision>
    <inertial>
      <origin rpy="0 0 0" xyz="-0.011687 4.8e-05 0.030393"/>
      <mass value="0.094464"/>
      <inertia ixx="9.9436e-05" ixy="1.1831e-07" ixz="-2.354e-05" iyy="0.00011232" iyz="2.5081e-07" izz="8.0987e-05"/>
    </inertial>
  </link>
  <link name="hand2">
    <visual>
      <origin rpy="1.570796327 0 0" xyz="0 0 0"/>
      <geometry>
        <mesh filename="package://nekonote_description/meshes/visual/end_effector_A/HAND2.stl"/>
      </geometry>
      <material name="">
        <color rgba="0.3 0.3 0.3 1"/>
      </material>
    </visual>
    <collision>
      <origin rpy="1.570796327 0 0" xyz="0 0 0"/>
      <geometry>
        <mesh filename="package://nekonote_description/meshes/collision/end_effector_A/HAND2.stl"/>
      </geometry>
    </collision>
    <inertial>
      <origin rpy="0 0 0" xyz="0.009859 0.03583 0.000117"/>
      <mass value="0.023997"/>
      <inertia ixx="1.0078e-05" ixy="3.3380e-07" ixz="4.766e-09" iyy="3.0823e-06" iyz="1.7785e-08" izz="8.9093e-06"/>
    </inertial>
  </link>
  <link name="tool0"/>
  <!-- joints -->
  <joint name="hand_base-hand1" type="fixed">
    <origin rpy="0 0 0" xyz="0 0 0"/>
    <parent link="hand_base"/>
    <child link="hand1"/>
    <axis xyz="0 0 1"/>
  </joint>
  <joint name="hand_joint" type="revolute">
    <origin rpy="0 0 0" xyz="0.004 0 0.0155"/>
    <parent link="hand1"/>
    <child link="hand2"/>
    <axis xyz="0 1 0"/>
    <limit effort="0" lower="0.01658" upper="1.1576" velocity="0"/>
  </joint>
  <joint name="hand2-tool0" type="fixed">
    <!-- TODO fix tool0 position-->
    <origin rpy="0 0 0" xyz="0 0 0.01"/>
    <parent link="hand2"/>
    <child link="tool0"/>
  </joint>
</robot>
